Workbook

Sheet Parámetros
A1: Parámetros del cálculo (un solo lugar: las fórmulas solo los leen)
A2: Celdas en azul = valores escritos a mano. Si cambia una ley o una tasa, se cambia SOLO aquí.
A3: Parámetro | B3: Valor | C3: Fuente | D3: Fecha de consulta
A4: RMV (S/) | B4: 1230 | C4: D.S. N.º 015-2026-TR (El Peruano, 28/09/2026), vigente desde el 01/10/2026 | D4: 28/10/2026
A5: % asignación familiar | B5: 0.1 | C5: Ley 25129 | D5: 28/10/2026
A6: Asignación familiar (S/) | B6: =ROUND(B4*B5,2) -> 123 | C6: Calculado: RMV × 10% | D6: 28/10/2026
A7: Días del mes | B7: 30 | C7: Convención del enunciado (mes de 30 días) | D7: 28/10/2026
A8: Horas por día | B8: 8 | C8: Jornada ordinaria de 8 horas | D8: 28/10/2026
A9: Factor horas extras 25% | B9: 1.25 | C9: Normas de jornada y sobretiempo (primeras horas) | D9: 28/10/2026
A10: Factor horas extras 35% | B10: 1.35 | C10: Normas de jornada y sobretiempo (horas siguientes) | D10: 28/10/2026
A11: Tasa ONP | B11: 0.13 | C11: D.L. 19990 | D11: 28/10/2026
A12: Tasa EsSalud (empleador) | B12: 0.09 | C12: Ley 26790 | D12: 28/10/2026
A15: Tasas de AFP (sobre el total de remuneraciones)
A16: AFP | B16: Fondo | C16: Comisión | D16: Seguro | E16: Fuente | F16: Fecha de consulta
A17: AFP Ejemplo | B17: 0.1 | C17: 0.016 | D17: 0.0135 | E17: Enunciado del tema (solo para los casos de prueba) | F17: 28/10/2026
A18: Habitat | B18: 0.1 | C18: 0.0147 | D18: 0.0137 | E18: SBS, comisión sobre flujo y prima de seguros, devengue oct-2026 | F18: 28/10/2026
A19: Integra | B19: 0.1 | C19: 0.0155 | D19: 0.0137 | E19: SBS, comisión sobre flujo y prima de seguros, devengue oct-2026 | F19: 28/10/2026
A20: Prima | B20: 0.1 | C20: 0.016 | D20: 0.0137 | E20: SBS, comisión sobre flujo y prima de seguros, devengue oct-2026 | F20: 28/10/2026
A21: Profuturo | B21: 0.1 | C21: 0.0169 | D21: 0.0137 | E21: SBS, comisión sobre flujo y prima de seguros, devengue oct-2026 | F21: 28/10/2026
A23: Nota: las tasas reales son de comisión sobre flujo. Un afiliado con comisión mixta paga 0% sobre flujo (cobra sobre saldo), así que en un caso real se confirma el esquema del trabajador.
A25: Renta de 5.ª categoría (nivel 3 · reto, versión simplificada)
A26: Parámetro | B26: Valor | C26: Fuente | D26: Fecha de consulta
A27: UIT 2026 (S/) | B27: 5500 | C27: D.S. N.º 301-2025-EF | D27: 28/10/2026
A28: UIT deducibles al año | B28: 7 | C28: Art. 46 de la Ley del Impuesto a la Renta | D28: 28/10/2026
A29: Meses que se proyectan | B29: 12 | C29: Simplificación: mismo sueldo los 12 meses | D29: 28/10/2026
A30: Gratificaciones al año | B30: 2 | C30: Ley 27735 (julio y diciembre) | D30: 28/10/2026
A31: Bonificación extraordinaria | B31: 0.09 | C31: Ley 30334 (9% de cada gratificación) | D31: 28/10/2026
A33: Tramo | B33: Desde (S/) | C33: Hasta (S/) | D33: Tasa | E33: Tramo en UIT | F33: Fuente
A34: 1 | B34: 0 | C34: =5*UIT -> 27500 | D34: 0.08 | E34: Hasta 5 UIT | F34: Art. 53 de la Ley del Impuesto a la Renta
A35: 2 | B35: =C34 -> 27500 | C35: =20*UIT -> 110000 | D35: 0.14 | E35: Más de 5 hasta 20 UIT | F35: Art. 53 de la Ley del Impuesto a la Renta
A36: 3 | B36: =C35 -> 110000 | C36: =35*UIT -> 192500 | D36: 0.17 | E36: Más de 20 hasta 35 UIT | F36: Art. 53 de la Ley del Impuesto a la Renta
A37: 4 | B37: =C36 -> 192500 | C37: =45*UIT -> 247500 | D37: 0.2 | E37: Más de 35 hasta 45 UIT | F37: Art. 53 de la Ley del Impuesto a la Renta
A38: 5 | B38: =C37 -> 247500 | C38: 1e+15 | D38: 0.3 | E38: Más de 45 UIT (sin tope) | F38: Art. 53 de la Ley del Impuesto a la Renta

Sheet Boleta
A1: Boleta de ejemplo — cálculo del mes
A2: Escribe solo en las celdas amarillas. Todo lo demás son fórmulas (la columna D muestra la fórmula de cada monto).
A3: Empresa: Comercial Andina Ejemplo S.A.C. · RUC 20000000000 (ficticio)
B4: Dato de entrada | C4: Valor | D4: Regla
B5: Nombre del trabajador | C5: Trabajador de ejemplo | D5: Ficticio
B6: Sueldo básico (S/) | C6: 3000 | D6: Mayor que cero
B7: Días laborados | C7: 30 | D7: Entero entre 1 y 30
B8: ¿Tiene hijos? | C8: Sí | D8: No / Sí
B9: Sistema de pensiones | C9: AFP | D9: ONP / AFP
B10: AFP | C10: AFP Ejemplo | D10: Solo se usa si el sistema es AFP
B11: Horas extras al 25% | C11: 4 | D11: Mayor o igual a cero
B12: Horas extras al 35% | C12: 4 | D12: Mayor o igual a cero
B13: Adelantos (S/) | C13: 200 | D13: Mayor o igual a cero
B14: ¿Calcular renta 5.ª? (reto) | C14: No | D14: No / Sí. En los casos 1 a 4 va No
B16: Validación | C16: =IF(OR(C6<=0,C7<1,C7>30,INT(C7)<>C7,C11<0,C12<0,C13<0),"Datos NO válidos: revisa sueldo (>0), días (1 a 30) y que horas/adelantos no sean negativos","Datos válidos") -> Datos válidos
A18: Bloque | B18: Concepto | C18: Monto (S/) | D18: Fórmula de la celda C | E18: En palabras
A19: REMUNERACIONES | B19: Sueldo computable | C19: =ROUND(C6*C7/DiasMes,2) -> 3000 | D19: =_xlfn.FORMULATEXT(C19) -> =ROUND(C6*C7/DiasMes,2) | E19: Sueldo básico ÷ 30 × días laborados
B20: Asignación familiar | C20: =IF(C8="Sí",AsigFam,0) -> 123 | D20: =_xlfn.FORMULATEXT(C20) -> =IF(C8="Sí",AsigFam,0) | E20: Si tiene hijos, 10% de la RMV. No depende de los días
B21: Valor hora (dato intermedio) | C21: =C6/DiasMes/HorasDia -> 12.5 | D21: =_xlfn.FORMULATEXT(C21) -> =C6/DiasMes/HorasDia | E21: Sueldo básico ÷ 30 ÷ 8. No va en la boleta ni se redondea
B22: Horas extras 25% | C22: =ROUND(C21*FactorHE25*C11,2) -> 62.5 | D22: =_xlfn.FORMULATEXT(C22) -> =ROUND(C21*FactorHE25*C11,2) | E22: Valor hora × 1.25 × horas al 25%
B23: Horas extras 35% | C23: =ROUND(C21*FactorHE35*C12,2) -> 67.5 | D23: =_xlfn.FORMULATEXT(C23) -> =ROUND(C21*FactorHE35*C12,2) | E23: Valor hora × 1.35 × horas al 35%
B24: Total remuneraciones | C24: =C19+C20+C22+C23 -> 3253 | D24: =_xlfn.FORMULATEXT(C24) -> =C19+C20+C22+C23 | E24: Suma de los conceptos (sin el valor hora)
A26: RETENCIONES / DESCUENTOS | B26: ONP (13%) | C26: =IF(C9="ONP",ROUND(C24*TasaONP,2),0) -> 0 | D26: =_xlfn.FORMULATEXT(C26) -> =IF(C9="ONP",ROUND(C24*TasaONP,2),0) | E26: Si está en ONP: 13% del total de remuneraciones
B27: AFP fondo | C27: =IF(C9="AFP",ROUND(C24*INDEX(TablaAFP,MATCH(C10,ListaAFP,0),2),2),0) -> 325.3 | D27: =_xlfn.FORMULATEXT(C27) -> =IF(C9="AFP",ROUND(C24*INDEX(TablaAFP,MATCH(C10,ListaAFP,0),2),2),0) | E27: Si está en AFP: total de remuneraciones × % de fondo de su AFP
B28: AFP comisión | C28: =IF(C9="AFP",ROUND(C24*INDEX(TablaAFP,MATCH(C10,ListaAFP,0),3),2),0) -> 52.05 | D28: =_xlfn.FORMULATEXT(C28) -> =IF(C9="AFP",ROUND(C24*INDEX(TablaAFP,MATCH(C10,ListaAFP,0),3),2),0) | E28: Si está en AFP: total de remuneraciones × % de comisión de su AFP
B29: AFP seguro | C29: =IF(C9="AFP",ROUND(C24*INDEX(TablaAFP,MATCH(C10,ListaAFP,0),4),2),0) -> 43.92 | D29: =_xlfn.FORMULATEXT(C29) -> =IF(C9="AFP",ROUND(C24*INDEX(TablaAFP,MATCH(C10,ListaAFP,0),4),2),0) | E29: Si está en AFP: total de remuneraciones × % de seguro de su AFP
B30: Renta 5.ª categoría (reto) | C30: =IF(C14="Sí",C49,0) -> 0 | D30: =_xlfn.FORMULATEXT(C30) -> =IF(C14="Sí",C49,0) | E30: Solo si se activa el reto: viene del cálculo de abajo
B31: Adelantos | C31: =ROUND(C13,2) -> 200 | D31: =_xlfn.FORMULATEXT(C31) -> =ROUND(C13,2) | E31: Se resta tal cual se ingresó
B32: Total descuentos | C32: =SUM(C26:C31) -> 621.27 | D32: =_xlfn.FORMULATEXT(C32) -> =SUM(C26:C31) | E32: Pensión (ONP o AFP) + renta + adelantos
A34: NETO | B34: NETO A PAGAR | C34: =C24-C32 -> 2631.73 | D34: =_xlfn.FORMULATEXT(C34) -> =C24-C32 | E34: Total remuneraciones − total descuentos
A36: APORTACIONES DEL EMPLEADOR | B36: EsSalud (9%) | C36: =ROUND(C24*TasaEsSalud,2) -> 292.77 | D36: =_xlfn.FORMULATEXT(C36) -> =ROUND(C24*TasaEsSalud,2) | E36: 9% del total de remuneraciones. Lo paga la empresa, no se descuenta
A38: EXTRA (análisis) | B38: Costo total para la empresa | C38: =C24+C36 -> 3545.77 | D38: =_xlfn.FORMULATEXT(C38) -> =C24+C36 | E38: Total remuneraciones + EsSalud
B39: % del bruto que llega como neto | C39: =IF(C24=0,0,C34/C24) -> 0.80901629 | D39: =_xlfn.FORMULATEXT(C39) -> =IF(C24=0,0,C34/C24) | E39: Neto ÷ total remuneraciones
A42: RENTA 5.ª (reto) | B42: Gratificaciones del año | C42: =ROUND((C6+C20)*NumGratif,2) -> 6246 | D42: =_xlfn.FORMULATEXT(C42) -> =ROUND((C6+C20)*NumGratif,2) | E42: (Sueldo básico + asignación familiar) × 2
B43: Bonificación extraordinaria | C43: =ROUND(C42*TasaBonif,2) -> 562.14 | D43: =_xlfn.FORMULATEXT(C43) -> =ROUND(C42*TasaBonif,2) | E43: 9% de las gratificaciones
B44: Renta bruta anual proyectada | C44: =C24*MesesAnio+C42+C43 -> 45844.14 | D44: =_xlfn.FORMULATEXT(C44) -> =C24*MesesAnio+C42+C43 | E44: Total remuneraciones × 12 + gratificaciones + bonificación
B45: Deducción de 7 UIT | C45: =UITDeduc*UIT -> 38500 | D45: =_xlfn.FORMULATEXT(C45) -> =UITDeduc*UIT | E45: 7 × 5,500 = 38,500 que no pagan impuesto
B46: Renta neta anual | C46: =MAX(0,C44-C45) -> 7344.14 | D46: =_xlfn.FORMULATEXT(C46) -> =MAX(0,C44-C45) | E46: Renta bruta − 7 UIT (si sale negativo, es 0)
B47: Impuesto anual | C47: =ROUND(SUMPRODUCT(TramoTasa,(C46>TramoDesde)*((C46<TramoHasta)*C46+(C46>=TramoHasta)*TramoHasta-TramoDesde)),2) -> 587.53 | D47: =_xlfn.FORMULATEXT(C47) -> =ROUND(SUMPRODUCT(TramoTasa,(C46>TramoDesde)*((C46<TramoHasta)*C46+(C46>=TramoHasta)*TramoHasta-TramoDesde)),2) | E47: Cada tasa (8%, 14%, 17%, 20%, 30%) solo sobre la parte de la renta que cae en su tramo
B49: Retención del mes | C49: =ROUND(C47/MesesAnio,2) -> 48.96 | D49: =_xlfn.FORMULATEXT(C49) -> =ROUND(C47/MesesAnio,2) | E49: Impuesto anual ÷ 12
...

Sheet Casos
A1: Casos de prueba y casos propios (misma lógica que la hoja Boleta, una columna por caso)
A2: Amarillo = datos de entrada. En las columnas 'Propio' va el sueldo de una oferta laboral publicada (≥ RMV); anota el enlace y la fecha en la tabla de fuentes de abajo.
A4: Concepto | B4: Caso 1 | C4: Caso 2 | D4: Caso 3 | E4: Caso 4 (evaluación) | F4: P1: caso 3 con ONP | G4: P3: caso 2 con 30 días | H4: Reto: caso 3 con renta 5.ª | I4: Propio · oferta 1 | J4: Propio · oferta 2
A5: Sueldo básico (S/) | B5: 2500 | C5: 1800 | D5: 3000 | E5: 4200 | F5: 3000 | G5: 1800 | H5: 3000
A6: Días laborados | B6: 30 | C6: 27 | D6: 30 | E6: 24 | F6: 30 | G6: 30 | H6: 30 | I6: 30 | J6: 30
A7: ¿Tiene hijos? | B7: No | C7: Sí | D7: Sí | E7: Sí | F7: Sí | G7: Sí | H7: Sí | I7: No | J7: No
A8: Sistema | B8: ONP | C8: ONP | D8: AFP | E8: AFP | F8: ONP | G8: ONP | H8: AFP | I8: AFP | J8: ONP
A9: AFP | B9: AFP Ejemplo | C9: AFP Ejemplo | D9: AFP Ejemplo | E9: AFP Ejemplo | F9: AFP Ejemplo | G9: AFP Ejemplo | H9: AFP Ejemplo | I9: Prima | J9: Habitat
A10: Horas extras 25% | B10: 0 | C10: 0 | D10: 4 | E10: 2 | F10: 4 | G10: 0 | H10: 4 | I10: 0 | J10: 0
A11: Horas extras 35% | B11: 0 | C11: 0 | D11: 4 | E11: 2 | F11: 4 | G11: 0 | H11: 4 | I11: 0 | J11: 0
A12: Adelantos (S/) | B12: 0 | C12: 0 | D12: 200 | E12: 100 | F12: 200 | G12: 0 | H12: 200 | I12: 0 | J12: 0
A13: ¿Renta 5.ª? | B13: No | C13: No | D13: No | E13: No | F13: No | G13: No | H13: Sí | I13: No | J13: No
A15: Cálculo | B15: Caso 1 | C15: Caso 2 | D15: Caso 3 | E15: Caso 4 (evaluación) | F15: P1: caso 3 con ONP | G15: P3: caso 2 con 30 días | H15: Reto: caso 3 con renta 5.ª | I15: Propio · oferta 1 | J15: Propio · oferta 2
A16: Sueldo computable | B16: =IF(B$5="","",ROUND(B5*B6/DiasMes,2)) -> 2500 | C16: =IF(C$5="","",ROUND(C5*C6/DiasMes,2)) -> 1620 | D16: =IF(D$5="","",ROUND(D5*D6/DiasMes,2)) -> 3000 | E16: =IF(E$5="","",ROUND(E5*E6/DiasMes,2)) -> 3360 | F16: =IF(F$5="","",ROUND(F5*F6/DiasMes,2)) -> 3000 | G16: =IF(G$5="","",ROUND(G5*G6/DiasMes,2)) -> 1800 | H16: =IF(H$5="","",ROUND(H5*H6/DiasMes,2)) -> 3000 | I16: =IF(I$5="","",ROUND(I5*I6/DiasMes,2)) | J16: =IF(J$5="","",ROUND(J5*J6/DiasMes,2))
A17: Asignación familiar | B17: =IF(B$5="","",IF(B7="Sí",AsigFam,0)) -> 0 | C17: =IF(C$5="","",IF(C7="Sí",AsigFam,0)) -> 123 | D17: =IF(D$5="","",IF(D7="Sí",AsigFam,0)) -> 123 | E17: =IF(E$5="","",IF(E7="Sí",AsigFam,0)) -> 123 | F17: =IF(F$5="","",IF(F7="Sí",AsigFam,0)) -> 123 | G17: =IF(G$5="","",IF(G7="Sí",AsigFam,0)) -> 123 | H17: =IF(H$5="","",IF(H7="Sí",AsigFam,0)) -> 123 | I17: =IF(I$5="","",IF(I7="Sí",AsigFam,0)) | J17: =IF(J$5="","",IF(J7="Sí",AsigFam,0))
A18: Valor hora | B18: =IF(B$5="","",B5/DiasMes/HorasDia) -> 10.416667 | C18: =IF(C$5="","",C5/DiasMes/HorasDia) -> 7.5 | D18: =IF(D$5="","",D5/DiasMes/HorasDia) -> 12.5 | E18: =IF(E$5="","",E5/DiasMes/HorasDia) -> 17.5 | F18: =IF(F$5="","",F5/DiasMes/HorasDia) -> 12.5 | G18: =IF(G$5="","",G5/DiasMes/HorasDia) -> 7.5 | H18: =IF(H$5="","",H5/DiasMes/HorasDia) -> 12.5 | I18: =IF(I$5="","",I5/DiasMes/HorasDia) | J18: =IF(J$5="","",J5/DiasMes/HorasDia)
A19: Horas extras 25% | B19: =IF(B$5="","",ROUND(B18*FactorHE25*B10,2)) -> 0 | C19: =IF(C$5="","",ROUND(C18*FactorHE25*C10,2)) -> 0 | D19: =IF(D$5="","",ROUND(D18*FactorHE25*D10,2)) -> 62.5 | E19: =IF(E$5="","",ROUND(E18*FactorHE25*E10,2)) -> 43.75 | F19: =IF(F$5="","",ROUND(F18*FactorHE25*F10,2)) -> 62.5 | G19: =IF(G$5="","",ROUND(G18*FactorHE25*G10,2)) -> 0 | H19: =IF(H$5="","",ROUND(H18*FactorHE25*H10,2)) -> 62.5 | I19: =IF(I$5="","",ROUND(I18*FactorHE25*I10,2)) | J19: =IF(J$5="","",ROUND(J18*FactorHE25*J10,2))
A20: Horas extras 35% | B20: =IF(B$5="","",ROUND(B18*FactorHE35*B11,2)) -> 0 | C20: =IF(C$5="","",ROUND(C18*FactorHE35*C11,2)) -> 0 | D20: =IF(D$5="","",ROUND(D18*FactorHE35*D11,2)) -> 67.5 | E20: =IF(E$5="","",ROUND(E18*FactorHE35*E11,2)) -> 47.25 | F20: =IF(F$5="","",ROUND(F18*FactorHE35*F11,2)) -> 67.5 | G20: =IF(G$5="","",ROUND(G18*FactorHE35*G11,2)) -> 0 | H20: =IF(H$5="","",ROUND(H18*FactorHE35*H11,2)) -> 67.5 | I20: =IF(I$5="","",ROUND(I18*FactorHE35*I11,2)) | J20: =IF(J$5="","",ROUND(J18*FactorHE35*J11,2))
A21: Total remuneraciones | B21: =IF(B$5="","",B16+B17+B19+B20) -> 2500 | C21: =IF(C$5="","",C16+C17+C19+C20) -> 1743 | D21: =IF(D$5="","",D16+D17+D19+D20) -> 3253 | E21: =IF(E$5="","",E16+E17+E19+E20) -> 3574 | F21: =IF(F$5="","",F16+F17+F19+F20) -> 3253 | G21: =IF(G$5="","",G16+G17+G19+G20) -> 1923 | H21: =IF(H$5="","",H16+H17+H19+H20) -> 3253 | I21: =IF(I$5="","",I16+I17+I19+I20) | J21: =IF(J$5="","",J16+J17+J19+J20)
A22: ONP | B22: =IF(B$5="","",IF(B8="ONP",ROUND(B21*TasaONP,2),0)) -> 325 | C22: =IF(C$5="","",IF(C8="ONP",ROUND(C21*TasaONP,2),0)) -> 226.59 | D22: =IF(D$5="","",IF(D8="ONP",ROUND(D21*TasaONP,2),0)) -> 0 | E22: =IF(E$5="","",IF(E8="ONP",ROUND(E21*TasaONP,2),0)) -> 0 | F22: =IF(F$5="","",IF(F8="ONP",ROUND(F21*TasaONP,2),0)) -> 422.89 | G22: =IF(G$5="","",IF(G8="ONP",ROUND(G21*TasaONP,2),0)) -> 249.99 | H22: =IF(H$5="","",IF(H8="ONP",ROUND(H21*TasaONP,2),0)) -> 0 | I22: =IF(I$5="","",IF(I8="ONP",ROUND(I21*TasaONP,2),0)) | J22: =IF(J$5="","",IF(J8="ONP",ROUND(J21*TasaONP,2),0))
A23: AFP fondo | B23: =IF(B$5="","",IF(B8="AFP",ROUND(B21*INDEX(TablaAFP,MATCH(B9,ListaAFP,0),2),2),0)) -> 0 | C23: =IF(C$5="","",IF(C8="AFP",ROUND(C21*INDEX(TablaAFP,MATCH(C9,ListaAFP,0),2),2),0)) -> 0 | D23: =IF(D$5="","",IF(D8="AFP",ROUND(D21*INDEX(TablaAFP,MATCH(D9,ListaAFP,0),2),2),0)) -> 325.3 | E23: =IF(E$5="","",IF(E8="AFP",ROUND(E21*INDEX(TablaAFP,MATCH(E9,ListaAFP,0),2),2),0)) -> 357.4 | F23: =IF(F$5="","",IF(F8="AFP",ROUND(F21*INDEX(TablaAFP,MATCH(F9,ListaAFP,0),2),2),0)) -> 0 | G23: =IF(G$5="","",IF(G8="AFP",ROUND(G21*INDEX(TablaAFP,MATCH(G9,ListaAFP,0),2),2),0)) -> 0 | H23: =IF(H$5="","",IF(H8="AFP",ROUND(H21*INDEX(TablaAFP,MATCH(H9,ListaAFP,0),2),2),0)) -> 325.3 | I23: =IF(I$5="","",IF(I8="AFP",ROUND(I21*INDEX(TablaAFP,MATCH(I9,ListaAFP,0),2),2),0)) | J23: =IF(J$5="","",IF(J8="AFP",ROUND(J21*INDEX(TablaAFP,MATCH(J9,ListaAFP,0),2),2),0))
A24: AFP comisión | B24: =IF(B$5="","",IF(B8="AFP",ROUND(B21*INDEX(TablaAFP,MATCH(B9,ListaAFP,0),3),2),0)) -> 0 | C24: =IF(C$5="","",IF(C8="AFP",ROUND(C21*INDEX(TablaAFP,MATCH(C9,ListaAFP,0),3),2),0)) -> 0 | D24: =IF(D$5="","",IF(D8="AFP",ROUND(D21*INDEX(TablaAFP,MATCH(D9,ListaAFP,0),3),2),0)) -> 52.05 | E24: =IF(E$5="","",IF(E8="AFP",ROUND(E21*INDEX(TablaAFP,MATCH(E9,ListaAFP,0),3),2),0)) -> 57.18 | F24: =IF(F$5="","",IF(F8="AFP",ROUND(F21*INDEX(TablaAFP,MATCH(F9,ListaAFP,0),3),2),0)) -> 0 | G24: =IF(G$5="","",IF(G8="AFP",ROUND(G21*INDEX(TablaAFP,MATCH(G9,ListaAFP,0),3),2),0)) -> 0 | H24: =IF(H$5="","",IF(H8="AFP",ROUND(H21*INDEX(TablaAFP,MATCH(H9,ListaAFP,0),3),2),0)) -> 52.05 | I24: =IF(I$5="","",IF(I8="AFP",ROUND(I21*INDEX(TablaAFP,MATCH(I9,ListaAFP,0),3),2),0)) | J24: =IF(J$5="","",IF(J8="AFP",ROUND(J21*INDEX(TablaAFP,MATCH(J9,ListaAFP,0),3),2),0))
A25: AFP seguro | B25: =IF(B$5="","",IF(B8="AFP",ROUND(B21*INDEX(TablaAFP,MATCH(B9,ListaAFP,0),4),2),0)) -> 0 | C25: =IF(C$5="","",IF(C8="AFP",ROUND(C21*INDEX(TablaAFP,MATCH(C9,ListaAFP,0),4),2),0)) -> 0 | D25: =IF(D$5="","",IF(D8="AFP",ROUND(D21*INDEX(TablaAFP,MATCH(D9,ListaAFP,0),4),2),0)) -> 43.92 | E25: =IF(E$5="","",IF(E8="AFP",ROUND(E21*INDEX(TablaAFP,MATCH(E9,ListaAFP,0),4),2),0)) -> 48.25 | F25: =IF(F$5="","",IF(F8="AFP",ROUND(F21*INDEX(TablaAFP,MATCH(F9,ListaAFP,0),4),2),0)) -> 0 | G25: =IF(G$5="","",IF(G8="AFP",ROUND(G21*INDEX(TablaAFP,MATCH(G9,ListaAFP,0),4),2),0)) -> 0 | H25: =IF(H$5="","",IF(H8="AFP",ROUND(H21*INDEX(TablaAFP,MATCH(H9,ListaAFP,0),4),2),0)) -> 43.92 | I25: =IF(I$5="","",IF(I8="AFP",ROUND(I21*INDEX(TablaAFP,MATCH(I9,ListaAFP,0),4),2),0)) | J25: =IF(J$5="","",IF(J8="AFP",ROUND(J21*INDEX(TablaAFP,MATCH(J9,ListaAFP,0),4),2),0))
A26: Renta 5.ª (reto) | B26: =IF(B$5="","",IF(B13="Sí",B38,0)) -> 0 | C26: =IF(C$5="","",IF(C13="Sí",C38,0)) -> 0 | D26: =IF(D$5="","",IF(D13="Sí",D38,0)) -> 0 | E26: =IF(E$5="","",IF(E13="Sí",E38,0)) -> 0 | F26: =IF(F$5="","",IF(F13="Sí",F38,0)) -> 0 | G26: =IF(G$5="","",IF(G13="Sí",G38,0)) -> 0 | H26: =IF(H$5="","",IF(H13="Sí",H38,0)) -> 48.96 | I26: =IF(I$5="","",IF(I13="Sí",I38,0)) | J26: =IF(J$5="","",IF(J13="Sí",J38,0))
A27: Adelantos | B27: =IF(B$5="","",ROUND(B12,2)) -> 0 | C27: =IF(C$5="","",ROUND(C12,2)) -> 0 | D27: =IF(D$5="","",ROUND(D12,2)) -> 200 | E27: =IF(E$5="","",ROUND(E12,2)) -> 100 | F27: =IF(F$5="","",ROUND(F12,2)) -> 200 | G27: =IF(G$5="","",ROUND(G12,2)) -> 0 | H27: =IF(H$5="","",ROUND(H12,2)) -> 200 | I27: =IF(I$5="","",ROUND(I12,2)) | J27: =IF(J$5="","",ROUND(J12,2))
A28: Total descuentos | B28: =IF(B$5="","",SUM(B22:B27)) -> 325 | C28: =IF(C$5="","",SUM(C22:C27)) -> 226.59 | D28: =IF(D$5="","",SUM(D22:D27)) -> 621.27 | E28: =IF(E$5="","",SUM(E22:E27)) -> 562.83 | F28: =IF(F$5="","",SUM(F22:F27)) -> 622.89 | G28: =IF(G$5="","",SUM(G22:G27)) -> 249.99 | H28: =IF(H$5="","",SUM(H22:H27)) -> 670.23 | I28: =IF(I$5="","",SUM(I22:I27)) | J28: =IF(J$5="","",SUM(J22:J27))
A29: NETO A PAGAR | B29: =IF(B$5="","",B21-B28) -> 2175 | C29: =IF(C$5="","",C21-C28) -> 1516.41 | D29: =IF(D$5="","",D21-D28) -> 2631.73 | E29: =IF(E$5="","",E21-E28) -> 3011.17 | F29: =IF(F$5="","",F21-F28) -> 2630.11 | G29: =IF(G$5="","",G21-G28) -> 1673.01 | H29: =IF(H$5="","",H21-H28) -> 2582.77 | I29: =IF(I$5="","",I21-I28) | J29: =IF(J$5="","",J21-J28)
A30: EsSalud (empleador) | B30: =IF(B$5="","",ROUND(B21*TasaEsSalud,2)) -> 225 | C30: =IF(C$5="","",ROUND(C21*TasaEsSalud,2)) -> 156.87 | D30: =IF(D$5="","",ROUND(D21*TasaEsSalud,2)) -> 292.77 | E30: =IF(E$5="","",ROUND(E21*TasaEsSalud,2)) -> 321.66 | F30: =IF(F$5="","",ROUND(F21*TasaEsSalud,2)) -> 292.77 | G30: =IF(G$5="","",ROUND(G21*TasaEsSalud,2)) -> 173.07 | H30: =IF(H$5="","",ROUND(H21*TasaEsSalud,2)) -> 292.77 | I30: =IF(I$5="","",ROUND(I21*TasaEsSalud,2)) | J30: =IF(J$5="","",ROUND(J21*TasaEsSalud,2))
A31: Costo para la empresa | B31: =IF(B$5="","",B21+B30) -> 2725 | C31: =IF(C$5="","",C21+C30) -> 1899.87 | D31: =IF(D$5="","",D21+D30) -> 3545.77 | E31: =IF(E$5="","",E21+E30) -> 3895.66 | F31: =IF(F$5="","",F21+F30) -> 3545.77 | G31: =IF(G$5="","",G21+G30) -> 2096.07 | H31: =IF(H$5="","",H21+H30) -> 3545.77 | I31: =IF(I$5="","",I21+I30) | J31: =IF(J$5="","",J21+J30)
A32: % del bruto que llega como neto | B32: =IF(B$5="","",IF(B21=0,0,B29/B21)) -> 0.87 | C32: =IF(C$5="","",IF(C21=0,0,C29/C21)) -> 0.87 | D32: =IF(D$5="","",IF(D21=0,0,D29/D21)) -> 0.80901629 | E32: =IF(E$5="","",IF(E21=0,0,E29/E21)) -> 0.84252098 | F32: =IF(F$5="","",IF(F21=0,0,F29/F21)) -> 0.80851829 | G32: =IF(G$5="","",IF(G21=0,0,G29/G21)) -> 0.87 | H32: =IF(H$5="","",IF(H21=0,0,H29/H21)) -> 0.79396557 | I32: =IF(I$5="","",IF(I21=0,0,I29/I21)) | J32: =IF(J$5="","",IF(J21=0,0,J29/J21))
A33: Gratificaciones del año | B33: =IF(B$5="","",ROUND((B5+B17)*NumGratif,2)) -> 5000 | C33: =IF(C$5="","",ROUND((C5+C17)*NumGratif,2)) -> 3846 | D33: =IF(D$5="","",ROUND((D5+D17)*NumGratif,2)) -> 6246 | E33: =IF(E$5="","",ROUND((E5+E17)*NumGratif,2)) -> 8646 | F33: =IF(F$5="","",ROUND((F5+F17)*NumGratif,2)) -> 6246 | G33: =IF(G$5="","",ROUND((G5+G17)*NumGratif,2)) -> 3846 | H33: =IF(H$5="","",ROUND((H5+H17)*NumGratif,2)) -> 6246 | I33: =IF(I$5="","",ROUND((I5+I17)*NumGratif,2)) | J33: =IF(J$5="","",ROUND((J5+J17)*NumGratif,2))
A34: Bonificación extraordinaria | B34: =IF(B$5="","",ROUND(B33*TasaBonif,2)) -> 450 | C34: =IF(C$5="","",ROUND(C33*TasaBonif,2)) -> 346.14 | D34: =IF(D$5="","",ROUND(D33*TasaBonif,2)) -> 562.14 | E34: =IF(E$5="","",ROUND(E33*TasaBonif,2)) -> 778.14 | F34: =IF(F$5="","",ROUND(F33*TasaBonif,2)) -> 562.14 | G34: =IF(G$5="","",ROUND(G33*TasaBonif,2)) -> 346.14 | H34: =IF(H$5="","",ROUND(H33*TasaBonif,2)) -> 562.14 | I34: =IF(I$5="","",ROUND(I33*TasaBonif,2)) | J34: =IF(J$5="","",ROUND(J33*TasaBonif,2))
A35: Renta bruta anual proyectada | B35: =IF(B$5="","",B21*MesesAnio+B33+B34) -> 35450 | C35: =IF(C$5="","",C21*MesesAnio+C33+C34) -> 25108.14 | D35: =IF(D$5="","",D21*MesesAnio+D33+D34) -> 45844.14 | E35: =IF(E$5="","",E21*MesesAnio+E33+E34) -> 52312.14 | F35: =IF(F$5="","",F21*MesesAnio+F33+F34) -> 45844.14 | G35: =IF(G$5="","",G21*MesesAnio+G33+G34) -> 27268.14 | H35: =IF(H$5="","",H21*MesesAnio+H33+H34) -> 45844.14 | I35: =IF(I$5="","",I21*MesesAnio+I33+I34) | J35: =IF(J$5="","",J21*MesesAnio+J33+J34)
A36: Renta neta anual (− 7 UIT) | B36: =IF(B$5="","",MAX(0,B35-UITDeduc*UIT)) -> 0 | C36: =IF(C$5="","",MAX(0,C35-UITDeduc*UIT)) -> 0 | D36: =IF(D$5="","",MAX(0,D35-UITDeduc*UIT)) -> 7344.14 | E36: =IF(E$5="","",MAX(0,E35-UITDeduc*UIT)) -> 13812.14 | F36: =IF(F$5="","",MAX(0,F35-UITDeduc*UIT)) -> 7344.14 | G36: =IF(G$5="","",MAX(0,G35-UITDeduc*UIT)) -> 0 | H36: =IF(H$5="","",MAX(0,H35-UITDeduc*UIT)) -> 7344.14 | I36: =IF(I$5="","",MAX(0,I35-UITDeduc*UIT)) | J36: =IF(J$5="","",MAX(0,J35-UITDeduc*UIT))
A37: Impuesto anual | B37: =IF(B$5="","",ROUND(SUMPRODUCT(TramoTasa,(B36>TramoDesde)*((B36<TramoHasta)*B36+(B36>=TramoHasta)*TramoHasta-TramoDesde)),2)) -> 0 | C37: =IF(C$5="","",ROUND(SUMPRODUCT(TramoTasa,(C36>TramoDesde)*((C36<TramoHasta)*C36+(C36>=TramoHasta)*TramoHasta-TramoDesde)),2)) -> 0 | D37: =IF(D$5="","",ROUND(SUMPRODUCT(TramoTasa,(D36>TramoDesde)*((D36<TramoHasta)*D36+(D36>=TramoHasta)*TramoHasta-TramoDesde)),2)) -> 587.53 | E37: =IF(E$5="","",ROUND(SUMPRODUCT(TramoTasa,(E36>TramoDesde)*((E36<TramoHasta)*E36+(E36>=TramoHasta)*TramoHasta-TramoDesde)),2)) -> 1104.97 | F37: =IF(F$5="","",ROUND(SUMPRODUCT(TramoTasa,(F36>TramoDesde)*((F36<TramoHasta)*F36+(F36>=TramoHasta)*TramoHasta-TramoDesde)),2)) -> 587.53 | G37: =IF(G$5="","",ROUND(SUMPRODUCT(TramoTasa,(G36>TramoDesde)*((G36<TramoHasta)*G36+(G36>=TramoHasta)*TramoHasta-TramoDesde)),2)) -> 0 | H37: =IF(H$5="","",ROUND(SUMPRODUCT(TramoTasa,(H36>TramoDesde)*((H36<TramoHasta)*H36+(H36>=TramoHasta)*TramoHasta-TramoDesde)),2)) -> 587.53 | I37: =IF(I$5="","",ROUND(SUMPRODUCT(TramoTasa,(I36>TramoDesde)*((I36<TramoHasta)*I36+(I36>=TramoHasta)*TramoHasta-TramoDesde)),2)) | J37: =IF(J$5="","",ROUND(SUMPRODUCT(TramoTasa,(J36>TramoDesde)*((J36<TramoHasta)*J36+(J36>=TramoHasta)*TramoHasta-TramoDesde)),2))
A38: Retención mensual de renta | B38: =IF(B$5="","",ROUND(B37/MesesAnio,2)) -> 0 | C38: =IF(C$5="","",ROUND(C37/MesesAnio,2)) -> 0 | D38: =IF(D$5="","",ROUND(D37/MesesAnio,2)) -> 48.96 | E38: =IF(E$5="","",ROUND(E37/MesesAnio,2)) -> 92.08 | F38: =IF(F$5="","",ROUND(F37/MesesAnio,2)) -> 48.96 | G38: =IF(G$5="","",ROUND(G37/MesesAnio,2)) -> 0 | H38: =IF(H$5="","",ROUND(H37/MesesAnio,2)) -> 48.96 | I38: =IF(I$5="","",ROUND(I37/MesesAnio,2)) | J38: =IF(J$5="","",ROUND(J37/MesesAnio,2))
A40: Control cruzado
A41: Neto según el enunciado | B41: 2175 | C41: 1516.41 | D41: 2631.73 | E41: Lo revisa el docente | F41: — | G41: — | H41: —
A42: Diferencia Excel − enunciado | B42: =B29-B41 -> 0 | C42: =C29-C41 -> 0 | D42: =D29-D41 -> 0
A43: Neto que muestra la app | B43: 2175 | C43: 1516.41 | D43: 2631.73 | E43: 3011.17 | F43: 2630.11 | G43: 1673.01 | H43: 2582.77
...

Sheet Explicación
A1: Cómo se calcula la boleta, explicado para alguien que no sabe contabilidad
A2: Ejemplo numérico: Caso 3 (sueldo S/ 3,000, 30 días, con hijos, AFP Ejemplo, 4 h al 25%, 4 h al 35%, adelanto S/ 200). Regla general: cada concepto se redondea a 2 decimales y después se suman.
A4: Concepto | B4: La fórmula en palabras | C4: Fórmula en Excel (hoja Boleta) | D4: Ejemplo con el caso 3 | E4: Resultado (S/)
A5: Sueldo computable | B5: Lo que te toca del sueldo según los días que trabajaste. El mes se cuenta como de 30 días: divides el sueldo entre 30 para saber cuánto vale un día y lo multiplicas por los días laborados. | C5: =_xlfn.FORMULATEXT(Boleta!C19) -> =ROUND(C6*C7/DiasMes,2) | D5: 3,000 ÷ 30 × 30 | E5: =Casos!D16 -> 3000
A6: Asignación familiar | B6: Un monto fijo para quien tiene hijos: el 10% del sueldo mínimo (RMV). No baja aunque faltes días. | C6: =_xlfn.FORMULATEXT(Boleta!C20) -> =IF(C8="Sí",AsigFam,0) | D6: 10% × 1,230 | E6: =Casos!D17 -> 123
A7: Valor hora | B7: Cuánto vale una hora normal: sueldo entre 30 días y entre 8 horas. Solo sirve para las horas extras; no aparece en la boleta. | C7: =_xlfn.FORMULATEXT(Boleta!C21) -> =C6/DiasMes/HorasDia | D7: 3,000 ÷ 30 ÷ 8 | E7: =Casos!D18 -> 12.5
A8: Horas extras al 25% | B8: Las primeras horas extra se pagan un 25% más caras que una hora normal: valor hora × 1.25 × horas. | C8: =_xlfn.FORMULATEXT(Boleta!C22) -> =ROUND(C21*FactorHE25*C11,2) | D8: 12.50 × 1.25 × 4 | E8: =Casos!D19 -> 62.5
A9: Horas extras al 35% | B9: Las siguientes se pagan un 35% más caras: valor hora × 1.35 × horas. | C9: =_xlfn.FORMULATEXT(Boleta!C23) -> =ROUND(C21*FactorHE35*C12,2) | D9: 12.50 × 1.35 × 4 | E9: =Casos!D20 -> 67.5
A10: Total remuneraciones | B10: Todo lo que ganaste en el mes antes de descuentos (el bruto). | C10: =_xlfn.FORMULATEXT(Boleta!C24) -> =C19+C20+C22+C23 | D10: 3,000 + 123 + 62.50 + 67.50 | E10: =Casos!D21 -> 3253
A11: ONP | B11: Si estás en la ONP, se retiene el 13% del bruto para tu pensión. | C11: =_xlfn.FORMULATEXT(Boleta!C26) -> =IF(C9="ONP",ROUND(C24*TasaONP,2),0) | D11: No aplica (está en AFP) | E11: =Casos!D22 -> 0
A12: AFP fondo | B12: Si estás en AFP, el 10% del bruto va a tu cuenta personal de jubilación. | C12: =_xlfn.FORMULATEXT(Boleta!C27) -> =IF(C9="AFP",ROUND(C24*INDEX(TablaAFP,MATCH(C10,ListaAFP,0),2),2),0) | D12: 3,253 × 10% | E12: =Casos!D23 -> 325.3
A13: AFP comisión | B13: Lo que cobra la AFP por administrar tu dinero: un % del bruto (cambia según la AFP). | C13: =_xlfn.FORMULATEXT(Boleta!C28) -> =IF(C9="AFP",ROUND(C24*INDEX(TablaAFP,MATCH(C10,ListaAFP,0),3),2),0) | D13: 3,253 × 1.60% = 52.048 | E13: =Casos!D24 -> 52.05
A14: AFP seguro | B14: Un seguro de invalidez y sobrevivencia: otro % del bruto. | C14: =_xlfn.FORMULATEXT(Boleta!C29) -> =IF(C9="AFP",ROUND(C24*INDEX(TablaAFP,MATCH(C10,ListaAFP,0),4),2),0) | D14: 3,253 × 1.35% = 43.9155 | E14: =Casos!D25 -> 43.92
A15: Adelantos | B15: Dinero que ya te dieron antes en el mes; se resta tal cual. | C15: =_xlfn.FORMULATEXT(Boleta!C31) -> =ROUND(C13,2) | D15: 200 | E15: =Casos!D27 -> 200
A16: Total descuentos | B16: La pensión (ONP o AFP) más la renta (si aplica) y los adelantos. | C16: =_xlfn.FORMULATEXT(Boleta!C32) -> =SUM(C26:C31) | D16: 325.30 + 52.05 + 43.92 + 200 | E16: =Casos!D28 -> 621.27
A17: Neto a pagar | B17: Lo que realmente llega a tu cuenta: bruto menos descuentos. | C17: =_xlfn.FORMULATEXT(Boleta!C34) -> =C24-C32 | D17: 3,253.00 − 621.27 | E17: =Casos!D29 -> 2631.73
A18: EsSalud | B18: Seguro de salud que paga la empresa aparte: 9% del bruto. NO se le quita al trabajador. | C18: =_xlfn.FORMULATEXT(Boleta!C36) -> =ROUND(C24*TasaEsSalud,2) | D18: 3,253 × 9% = 292.77 | E18: =Casos!D30 -> 292.77
A20: Nivel 3 (reto): renta de 5.ª categoría — ejemplo con el caso 3
A21: Paso | B21: La fórmula en palabras | C21: Fórmula en Excel (hoja Boleta) | D21: Ejemplo con el caso 3 | E21: Resultado (S/)
A22: Gratificaciones del año | B22: En julio y diciembre se recibe un sueldo extra cada vez (sueldo + asignación familiar). | C22: =_xlfn.FORMULATEXT(Boleta!C42) -> =ROUND((C6+C20)*NumGratif,2) | D22: (3,000 + 123) × 2 | E22: =Casos!H33 -> 6246
A23: Bonificación extraordinaria | B23: Encima de cada gratificación se paga el 9% que la empresa ya no aporta a EsSalud. | C23: =_xlfn.FORMULATEXT(Boleta!C43) -> =ROUND(C42*TasaBonif,2) | D23: 6,246 × 9% | E23: =Casos!H34 -> 562.14
A24: Renta anual proyectada | B24: Se imagina que ganas lo mismo todo el año: el bruto del mes × 12 + gratificaciones + bonificación. | C24: =_xlfn.FORMULATEXT(Boleta!C44) -> =C24*MesesAnio+C42+C43 | D24: 3,253 × 12 + 6,246 + 562.14 | E24: =Casos!H35 -> 45844.14
A25: Renta neta | B25: Los primeros 7 UIT (S/ 38,500) no pagan impuesto, así que se restan. | C25: =_xlfn.FORMULATEXT(Boleta!C46) -> =MAX(0,C44-C45) | D25: 45,844.14 − 38,500 | E25: =Casos!H36 -> 7344.14
A26: Impuesto anual | B26: Funciona por escalones: el 8% solo sobre los primeros 5 UIT de renta neta, el 14% sobre lo que pasa de 5 hasta 20 UIT, y así. Aquí todo cae en el primer escalón. | C26: =_xlfn.FORMULATEXT(Boleta!C47) -> =ROUND(SUMPRODUCT(TramoTasa,(C46>TramoDesde)*((C46<TramoHasta)*C46+(C46>=TramoHasta)*TramoHasta-TramoDesde)),2) | D26: 7,344.14 × 8% | E26: =Casos!H37 -> 587.53
A27: Retención del mes | B27: La empresa reparte ese impuesto en 12 partes y descuenta una cada mes. | C27: =_xlfn.FORMULATEXT(Boleta!C49) -> =ROUND(C47/MesesAnio,2) | D27: 587.53 ÷ 12 | E27: =Casos!H38 -> 48.96
A28: Neto con renta | B28: El neto del caso 3 baja por la retención. | C28: =_xlfn.FORMULATEXT(Boleta!C34) -> =C24-C32 | D28: 2,631.73 − 48.96 | E28: =Casos!H29 -> 2582.77
A29: Simplificación: se asume el mismo sueldo los 12 meses y se divide el impuesto entre 12. La SUNAT usa divisores distintos según el mes (12, 9, 8, 5, 4) y descuenta lo ya retenido; con un sueldo fijo, el resultado mensual es casi el mismo.
A31: Preguntas de análisis
A32: Pregunta | B32: Respuesta | C32: Dato clave (calculado)
A33: 1. ONP o AFP (caso 3) | B33: Con ONP el neto sería S/ 2,630.11 y con AFP Ejemplo S/ 2,631.73: la AFP deja S/ 1.62 más este mes, porque su descuento total (12.95%) es un poco menor que el 13% de la ONP. Pero comparar porcentajes no basta: en la AFP el 10% del fondo es ahorro propio que se queda en tu cuenta y rinde (o pierde) según el mercado, mientras que en la ONP va a un fondo común y la pensión depende de cumplir los años de aportes. Además la comisión y el seguro cambian según la AFP. Lo que conviene depende de cuántos años vas a aportar, tu edad y la rentabilidad, no del descuento de un mes. | C33: =Casos!D29-Casos!F29 -> 1.62
A34: 2. Costo real para la empresa (caso 3) | B34: La empresa paga S/ 3,253.00 de remuneraciones más S/ 292.77 de EsSalud: el trabajador le cuesta S/ 3,545.77. De ese costo, el neto de S/ 2,631.73 es el 74.22%. Si sumamos el adelanto de S/ 200 que ya recibió en el mes, le llega el 79.86%. | C34: =Casos!D29/Casos!D31 -> 0.74221678
A35: 3. Días laborados (caso 2) | B35: Con 30 días el neto sería S/ 1,673.01 en vez de S/ 1,516.41: sube S/ 156.60. El bruto, en cambio, sube S/ 180 (3 días de sueldo). La diferencia en el neto es menor porque la ONP se queda con el 13% de esos S/ 180 (180 × 0.87 = 156.60). La asignación familiar no cambia porque no se prorratea por días. | C35: =Casos!G29-Casos!C29 -> 156.6
A36: 4. Horas extras (caso 3) | B36: Las horas extras suman S/ 130.00 (62.50 + 67.50) sobre un total de S/ 3,253.00, o sea el 4.00% (exactamente 3.996%) de las remuneraciones. | C36: =(Casos!D19+Casos!D20)/Casos!D21 -> 0.039963111
A37: 5. Con datos reales | B37: Se toma el sueldo de una oferta laboral publicada (columnas 'Propio' de la hoja Casos, con su enlace y fecha). La fila '% del bruto que llega como neto' da el resultado y se compara con el de dos compañeros. | C37: =IF(Casos!I5="","Falta el sueldo",Casos!I32) -> Falta el sueldo
A40: Tabla de fuentes
A41: Dato | B41: Valor | C41: Fuente | D41: Fecha de consulta
A42: RMV | B42: S/ 1,230.00 | C42: D.S. N.º 015-2026-TR, El Peruano (28/09/2026), vigente desde 01/10/2026 | D42: 28/10/2026
A43: Asignación familiar | B43: 10% de la RMV = S/ 123.00 | C43: Ley 25129 | D43: 28/10/2026
A44: ONP | B44: 13% | C44: D.L. 19990 | D44: 28/10/2026
A45: EsSalud | B45: 9% | C45: Ley 26790 | D45: 28/10/2026
...
